<?xml version="1.0"?>
<robot name="front_wheel" xmlns:xacro="http://ros.org/wiki/xacro">

	<xacro:macro name="front_wheel" params="wheel_prefix name_suffix parent_link scale *joint_pose">
        <link name="${wheel_prefix}wheel_link${name_suffix}">
			<inertial>
				<mass value="40.0" />
                <origin xyz="0 0 0" />
                <inertia  ixx="0.09202648863416213" ixy="0" ixz="0" iyy="0.1381436777977178" iyz="0" izz="0.09201819684669786" />
            </inertial>
			<visual>
                <origin xyz="0 0 0" rpy="0 0 0" />
				<geometry>
                    <mesh filename="file://$(find kart_description)/meshes/kart_front_wheel.stl" scale="${scale} ${scale} ${scale}"/>
				</geometry>
                <material name="${wheel_prefix}wheel_colour"/>
			</visual>
            <!-- <collision> -->
                <!-- <origin xyz="0 0 0" rpy="0 0 0" /> -->
                <!-- <geometry> -->
                    <!-- <mesh filename="file://$(find kart_description)/meshes/kart_front_wheel.stl" scale="${scale} ${scale} ${scale}"/> -->
                <!-- </geometry> -->
            <!-- </collision> -->
            <collision>
                <origin xyz="0 0 0" rpy="${PI/2} 0 0" />
                <geometry>
                    <cylinder radius="${4.8*scale}" length="${5.53*scale}"/>
                </geometry>
            </collision>
		</link>

        <joint name="${wheel_prefix}wheel${name_suffix}" type="continuous">
            <parent link="${parent_link}"/>
            <child link="${wheel_prefix}wheel_link${name_suffix}"/>
			<xacro:insert_block name="joint_pose"/>
            <axis xyz="0 1 0" />
            <limit lower="0" upper="0" effort="0" velocity="1000"/>
            <dynamics damping="0" friction="0.1" />
        </joint>

        <gazebo reference="${wheel_prefix}wheel_link${name_suffix}">
            <mu1 value="2.0"/>
            <mu2 value="2.0"/>
            <kp  value="1e8" />
            <kd  value="1.0" />
            <maxVel value="0" />
            <!-- <minDepth value="0.01" /> -->
            <!-- <fdir1 value="1 0 0"/> -->
        </gazebo>

	</xacro:macro>
</robot>
