<?xml version="1.0"?>
<robot name="rear_wheel" xmlns:xacro="http://ros.org/wiki/xacro">

	<xacro:macro name="rear_wheel" params="wheel_prefix name_suffix parent_link scale velocity_factor *joint_pose">
        <link name="${wheel_prefix}wheel_link${name_suffix}">
            <inertial>
                <mass value="40.0" />
                <origin xyz="0 0 0" />
                <inertia  ixx="0.1212163181196065" ixy="0" ixz="0" iyy="0.1619523893924397" iyz="0" izz="0.12118997888732516" />
            </inertial>
			<visual>
                <origin xyz="0 0 0" rpy="0 0 0" />
				<geometry>
                    <mesh filename="file://$(find kart_description)/meshes/kart_rear_wheel.stl" scale="${scale} ${scale} ${scale}"/>
				</geometry>
                <material name="${wheel_prefix}wheel_colour"/>
			</visual>
			<!-- <collision> -->
                <!-- <origin xyz="0 0 0" rpy="0 0 0" /> -->
				<!-- <geometry> -->
                    <!-- <mesh filename="file://$(find kart_description)/meshes/kart_rear_wheel.stl" scale="${scale} ${scale} ${scale}"/> -->
				<!-- </geometry> -->
			<!-- </collision> -->
            <collision>
                <origin xyz="0 0 0" rpy="${PI/2} 0 0" />
                <geometry>
                    <cylinder radius="${5.2*scale}" length="${7.32*scale}"/>
                </geometry>
            </collision>
		</link>

        <joint name="${wheel_prefix}wheel${name_suffix}" type="continuous">
            <parent link="${parent_link}"/>
            <child link="${wheel_prefix}wheel_link${name_suffix}"/>
			<xacro:insert_block name="joint_pose"/>
            <axis xyz="0 ${velocity_factor} 0" />
            <limit lower="0" upper="0" effort="10000" velocity="1000"/>
            <dynamics damping="1" friction="0.1" />
		</joint>

        <gazebo reference="${wheel_prefix}wheel_link${name_suffix}">
            <mu1 value="2.0"/>
            <mu2 value="2.0"/>
            <kp  value="1e8" />
            <kd  value="1" />
            <maxVel value="0" />
            <!-- <minDepth value="0.01" /> -->
            <!-- <fdir1 value="${velocity_factor} 0 0"/> -->
        </gazebo>

	</xacro:macro>
</robot>
